Workbook

Sheet Assumptions
A1: Valuation Model — Caesars Entertainment, Inc. (NASDAQ: CZR) | Fertitta Acquisition Analysis
A2: Assumptions & Key Parameters | All figures in USD millions unless noted
A3: COMPANY — CZR Financials (FY2025 Actuals)
A4: Revenue FY2025A ($M) | B4: 11500 | C4: CZR 8-K Full Year 2025, Feb 17 2026
A5: Adj. EBITDA FY2025A ($M) | B5: 3624 | C5: Same-store Adj. EBITDA; CZR 8-K FY2025
A6: Caesars Digital EBITDA FY2025 ($M) | B6: 236 | C6: Up 102% YoY; CZR 8-K FY2025
A7: D&A annual ($M) | B7: 1200 | C7: Est. ~10.4% of revenue per 10-K
A8: Maintenance capex ($M) | B8: 800 | C8: Est.; step-down per mgmt guidance 2026
A9: Change in NWC % of revenue growth | B9: 0.02 | C9: Low WC intensity in gaming ops
A10: Tax rate | B10: 0.22 | C10: Effective rate; CZR benefits from NOLs
A11: Net debt FY2025 ($M) | B11: 11013 | C11: Debt $11,900 - Cash $887; CZR 8-K FY2025
A12: Diluted shares outstanding (M) | B12: 185 | C12: Est. post-14.7M buybacks 2024-25
A14: DCF — WACC & Growth Assumptions
A15: WACC | B15: 0.085 | C15: Est: 55% equity × 11% Ke + 45% debt × 6% Kd × (1-22%)
A16: Terminal growth rate | B16: 0.025 | C16: Long-run US GDP; conservative for levered gaming
A17: Revenue growth FY2026E | B17: 0.04 | C17: Digital ramp + LV convention + new properties
A18: Revenue growth FY2027E | B18: 0.05 | C18: Digital profitability + full-year new openings
A19: Revenue growth FY2028E | B19: 0.05 | C19: Steady state; Digital fully scaled
A20: Revenue growth FY2029E | B20: 0.04 | C20: Normalization; LV Strip moderates
A21: Revenue growth FY2030E | B21: 0.035 | C21: Approaching terminal
A22: EBITDA margin FY2026E | B22: 0.33 | C22: Modest expansion; Digital drag reduces
A23: EBITDA margin FY2027E | B23: 0.34 | C23: Digital EBITDA positive; operating leverage
A24: EBITDA margin FY2028E | B24: 0.35 | C24: Approaching peer best-in-class
A25: EBITDA margin FY2029E | B25: 0.355 | C25: Sustained efficiency + debt reduction
A26: EBITDA margin FY2030E | B26: 0.36 | C26: Terminal margin assumption
A28: DEAL — Fertitta Acquisition Parameters
A29: Offer price per share ($) | B29: 31 | C29: Definitive agreement, May 28 2026
A30: Implied equity value ($M) | B30: 5735 | C30: 185M shares × $31.00
A31: Implied enterprise value ($M) | B31: 16748 | C31: Equity + $11,013M net debt
A32: Implied EV / EBITDA | B32: 8.91 | C32: EV / FY2025 Adj. EBITDA; InsideArbitrage
A33: Premium to unaffected price (%) | B33: 0.49 | C33: vs. Feb 25 2026; definitive agreement
A34: Premium to 30-day VWAP (%) | B34: 0.46 | C34: CZR press release May 28 2026
A36: VALUATION MULTIPLES — Sensitivity
A37: EV/EBITDA — low case | B37: 7 | C37: Peer median range floor
A38: EV/EBITDA — base case | B38: 8 | C38: Slight premium to peers; Digital value
A39: EV/EBITDA — high case | B39: 9.5 | C39: In-line with Fertitta deal

Sheet DCF Valuation
A1: DCF Valuation — Caesars Entertainment, Inc. | 5-Year Projection + Terminal Value
A2: Unlevered Free Cash Flow | WACC discount | USD Millions
B4: FY2026E | C4: FY2027E | D4: FY2028E | E4: FY2029E | F4: FY2030E | G4: Terminal | H4: Notes
A5: Revenue & EBITDA Projection
A6: Revenue ($M) | B6: =Assumptions!B4*(1+Assumptions!B17) -> 11960 | C6: =B6*(1+Assumptions!B18) -> 12558 | D6: =C6*(1+Assumptions!B19) -> 13185.9 | E6: =D6*(1+Assumptions!B20) -> 13713.336 | F6: =E6*(1+Assumptions!B21) -> 14193.303 | H6: FY2025 $11,500M base
A7: YoY growth | B7: =B6/Assumptions!B4-1 -> 0.04 | C7: =C6/B6-1 -> 0.05 | D7: =D6/C6-1 -> 0.05 | E7: =E6/D6-1 -> 0.04 | F7: =F6/E6-1 -> 0.035
A8: Adj. EBITDA ($M) | B8: =B6*Assumptions!B22 -> 3946.8 | C8: =C6*Assumptions!B23 -> 4269.72 | D8: =D6*Assumptions!B24 -> 4615.065 | E8: =E6*Assumptions!B25 -> 4868.2343 | F8: =F6*Assumptions!B26 -> 5109.589 | H8: Margin expands 31.5%→36.0% as Digital scales
A9: EBITDA margin | B9: =Assumptions!B22 -> 0.33 | C9: =Assumptions!B23 -> 0.34 | D9: =Assumptions!B24 -> 0.35 | E9: =Assumptions!B25 -> 0.355 | F9: =Assumptions!B26 -> 0.36
A10: Unlevered Free Cash Flow Build
A11: EBITDA ($M) | B11: =B8 -> 3946.8 | C11: =C8 -> 4269.72 | D11: =D8 -> 4615.065 | E11: =E8 -> 4868.2343 | F11: =F8 -> 5109.589
A12: (-) D&A ($M) | B12: =-Assumptions!B7 -> -1200 | C12: =-Assumptions!B7 -> -1200 | D12: =-Assumptions!B7 -> -1200 | E12: =-Assumptions!B7 -> -1200 | F12: =-Assumptions!B7 -> -1200
A13: EBIT ($M) | B13: =B11+B12 -> 2746.8 | C13: =C11+C12 -> 3069.72 | D13: =D11+D12 -> 3415.065 | E13: =E11+E12 -> 3668.2343 | F13: =F11+F12 -> 3909.589
A14: (-) Taxes on EBIT | B14: =IF(B13>0,B13*(-Assumptions!B10),0) -> -604.296 | C14: =IF(C13>0,C13*(-Assumptions!B10),0) -> -675.3384 | D14: =IF(D13>0,D13*(-Assumptions!B10),0) -> -751.3143 | E14: =IF(E13>0,E13*(-Assumptions!B10),0) -> -807.01154 | F14: =IF(F13>0,F13*(-Assumptions!B10),0) -> -860.10958
A15: NOPAT ($M) | B15: =B13+B14 -> 2142.504 | C15: =C13+C14 -> 2394.3816 | D15: =D13+D14 -> 2663.7507 | E15: =E13+E14 -> 2861.2227 | F15: =F13+F14 -> 3049.4794
A16: (+) D&A add-back ($M) | B16: =-B12 -> 1200 | C16: =-C12 -> 1200 | D16: =-D12 -> 1200 | E16: =-E12 -> 1200 | F16: =-F12 -> 1200
A17: (-) Capex ($M) | B17: =-Assumptions!B8 -> -800 | C17: =-Assumptions!B8 -> -800 | D17: =-Assumptions!B8 -> -800 | E17: =-Assumptions!B8 -> -800 | F17: =-Assumptions!B8 -> -800
A18: (-) Change in NWC ($M) | B18: =-(B6-Assumptions!B4)*Assumptions!B9 -> -9.2 | C18: =-(C6-B6)*Assumptions!B9 -> -11.96 | D18: =-(D6-C6)*Assumptions!B9 -> -12.558 | E18: =-(E6-D6)*Assumptions!B9 -> -10.54872 | F18: =-(F6-E6)*Assumptions!B9 -> -9.5993352
A19: Unlevered FCF ($M) | B19: =B15+B16+B17+B18 -> 2533.304 | C19: =C15+C16+C17+C18 -> 2782.4216 | D19: =D15+D16+D17+D18 -> 3051.1927 | E19: =E15+E16+E17+E18 -> 3250.674 | F19: =F15+F16+F17+F18 -> 3439.8801
A20: Discount factor (mid-year convention) | B20: =1/(1+Assumptions!B15)^(1-0.5) -> 0.96003072 | C20: =1/(1+Assumptions!B15)^(2-0.5) -> 0.88482094 | D20: =1/(1+Assumptions!B15)^(3-0.5) -> 0.81550317 | E20: =1/(1+Assumptions!B15)^(4-0.5) -> 0.75161583 | F20: =1/(1+Assumptions!B15)^(5-0.5) -> 0.69273348
A21: PV of FCF ($M) | B21: =B19*B20 -> 2432.0497 | C21: =C19*C20 -> 2461.9449 | D21: =D19*D20 -> 2488.2573 | E21: =E19*E20 -> 2443.258 | F21: =F19*F20 -> 2382.9201
A23: Terminal Value (Gordon Growth Method)
A24: Terminal year FCF ($M) | G24: =F19 -> 3439.8801
A25: Terminal growth rate | G25: =Assumptions!B16 -> 0.025
A26: WACC | G26: =Assumptions!B15 -> 0.085
A27: Terminal value (undiscounted, $M) | G27: =G24/(G26-G25) -> 57331.335
A28: PV of terminal value ($M) | G28: =G27/(1+Assumptions!B15)^5 -> 38127.942
A30: Enterprise Value Bridge → Equity Value Per Share
A31: Sum of PV of FCFs ($M) | B31: =SUM(B21:F21) -> 12208.43
A32: PV of terminal value ($M) | B32: =G28 -> 38127.942
A33: Enterprise Value — DCF ($M) | B33: =B31+B32 -> 50336.372
A34: (-) Net debt ($M) | B34: =-Assumptions!B11 -> -11013
A35: Equity Value — DCF ($M) | B35: =B33+B34 -> 39323.372
A36: Diluted shares (M) | B36: =Assumptions!B12 -> 185
A37: Implied share price — DCF ($) | B37: =B35/B36 -> 212.55877 | H37: Compare vs. Fertitta offer $31.00/share
A38: Terminal value as % of total EV | B38: =B32/B33 -> 0.75746305
A39: Implied EV/EBITDA (DCF vs. FY2025) | B39: =B33/Assumptions!B5 -> 13.889727
A41: Sensitivity — Implied Share Price: WACC × Terminal Growth Rate
A42: WACC → | B42: 0.075 | C42: 0.08 | D42: 0.085 | E42: 0.09 | F42: 0.095
A43: 0.015 | B43: =(B19/(1+0.075)^(1-0.5)+C19/(1+0.075)^(2-0.5)+D19/(1+0.075)^(3-0.5)+E19/(1+0.075)^(4-0.5)+F19/(1+0.075)^(5-0.5)+F19/(0.075-0.015)/(1+0.075)^5-Assumptions!B11)/Assumptions!B12 -> 223.86983 | C43: =(B19/(1+0.08)^(1-0.5)+C19/(1+0.08)^(2-0.5)+D19/(1+0.08)^(3-0.5)+E19/(1+0.08)^(4-0.5)+F19/(1+0.08)^(5-0.5)+F19/(0.08-0.015)/(1+0.08)^5-Assumptions!B11)/Assumptions!B12 -> 201.9148 | D43: =(B19/(1+0.085)^(1-0.5)+C19/(1+0.085)^(2-0.5)+D19/(1+0.085)^(3-0.5)+E19/(1+0.085)^(4-0.5)+F19/(1+0.085)^(5-0.5)+F19/(0.085-0.015)/(1+0.085)^5-Assumptions!B11)/Assumptions!B12 -> 183.11634 | E43: =(B19/(1+0.09)^(1-0.5)+C19/(1+0.09)^(2-0.5)+D19/(1+0.09)^(3-0.5)+E19/(1+0.09)^(4-0.5)+F19/(1+0.09)^(5-0.5)+F19/(0.09-0.015)/(1+0.09)^5-Assumptions!B11)/Assumptions!B12 -> 166.84236 | F43: =(B19/(1+0.095)^(1-0.5)+C19/(1+0.095)^(2-0.5)+D19/(1+0.095)^(3-0.5)+E19/(1+0.095)^(4-0.5)+F19/(1+0.095)^(5-0.5)+F19/(0.095-0.015)/(1+0.095)^5-Assumptions!B11)/Assumptions!B12 -> 152.61884
A44: 0.02 | B44: =(B19/(1+0.075)^(1-0.5)+C19/(1+0.075)^(2-0.5)+D19/(1+0.075)^(3-0.5)+E19/(1+0.075)^(4-0.5)+F19/(1+0.075)^(5-0.5)+F19/(0.075-0.02)/(1+0.075)^5-Assumptions!B11)/Assumptions!B12 -> 243.49373 | C44: =(B19/(1+0.08)^(1-0.5)+C19/(1+0.08)^(2-0.5)+D19/(1+0.08)^(3-0.5)+E19/(1+0.08)^(4-0.5)+F19/(1+0.08)^(5-0.5)+F19/(0.08-0.02)/(1+0.08)^5-Assumptions!B11)/Assumptions!B12 -> 218.13881 | D44: =(B19/(1+0.085)^(1-0.5)+C19/(1+0.085)^(2-0.5)+D19/(1+0.085)^(3-0.5)+E19/(1+0.085)^(4-0.5)+F19/(1+0.085)^(5-0.5)+F19/(0.085-0.02)/(1+0.085)^5-Assumptions!B11)/Assumptions!B12 -> 196.70515 | E44: =(B19/(1+0.09)^(1-0.5)+C19/(1+0.09)^(2-0.5)+D19/(1+0.09)^(3-0.5)+E19/(1+0.09)^(4-0.5)+F19/(1+0.09)^(5-0.5)+F19/(0.09-0.02)/(1+0.09)^5-Assumptions!B11)/Assumptions!B12 -> 178.35169 | F44: =(B19/(1+0.095)^(1-0.5)+C19/(1+0.095)^(2-0.5)+D19/(1+0.095)^(3-0.5)+E19/(1+0.095)^(4-0.5)+F19/(1+0.095)^(5-0.5)+F19/(0.095-0.02)/(1+0.095)^5-Assumptions!B11)/Assumptions!B12 -> 162.46166
...

Sheet Trading Comps
A1: Trading Comparables — Gaming & Hospitality Peers | Caesars Entertainment Valuation
A2: FY2025 Actuals | Sources: SEC 8-K filings, Feb 2026 | USD Millions
A4: Company | B4: Ticker | C4: Revenue ($M) | D4: Adj.EBITDA ($M) | E4: EBITDA margin | F4: Net debt ($M) | G4: Mkt cap ($M) | H4: EV ($M) | I4: EV/EBITDA | J4: Rev growth | K4: EBITDA margin | L4: Source
A5: MGM Resorts Intl. | B5: MGM | C5: 17500 | D5: 2400 | E5: 0.137 | F5: 7800 | G5: 9500 | H5: 17300 | I5: =H5/D5 -> 7.2083333 | J5: 0.017 | K5: 0.01 | L5: 8-K FY2025, Feb 5 2026; EV/EBITDA 16.4x per StockAnalysis
A6: Wynn Resorts | B6: WYNN | C6: 7140 | D6: 2100 | E6: 0.294 | F6: 4500 | G6: 10800 | H6: 15300 | I6: =H6/D6 -> 7.2857143 | J6: 0.001 | K6: -0.08 | L6: 8-K FY2025; EBITDA $1.69B TTM Macrotrends
A7: Boyd Gaming | B7: BYD | C7: 4090 | D7: 1350 | E7: 0.33 | F7: 1800 | G7: 6540 | H7: 8340 | I7: =H7/D7 -> 6.1777778 | J7: 0.051 | K7: 0.05 | L7: 8-K FY2025, Feb 5 2026
A8: PENN Entertainment | B8: PENN | C8: 6960 | D8: 830 | E8: 0.119 | F8: 2200 | G8: 3800 | H8: 6000 | I8: =H8/D8 -> 7.2289157 | J8: 0.058 | K8: 0.235 | L8: 8-K FY2025, Feb 26 2026
A9: Median peers | C9: =MEDIAN(C5:C8) -> 7050 | D9: =MEDIAN(D5:D8) -> 1725 | E9: =MEDIAN(E5:E8) -> 0.2155 | I9: =MEDIAN(I5:I8) -> 7.2186245 | J9: =MEDIAN(J5:J8) -> 0.034
A10: Mean peers | C10: =AVERAGE(C5:C8) -> 8922.5 | D10: =AVERAGE(D5:D8) -> 1670 | E10: =AVERAGE(E5:E8) -> 0.22 | I10: =AVERAGE(I5:I8) -> 6.9751853 | J10: =AVERAGE(J5:J8) -> 0.03175
A12: Caesars Entertainment ★ | B12: CZR | C12: 11500 | D12: 3624 | E12: =D12/C12 -> 0.31513043 | F12: 11013 | G12: 5735 | H12: 16748 | I12: =H12/D12 -> 4.6214128 | J12: 0.027 | K12: =D12/Assumptions!B5-1 -> 0 | L12: Deal: CZR press release May 28 2026
A15: Implied CZR Valuation — Applying Peer Multiples
A16: Multiple applied | C16: Median peers | D16: Mean peers | E16: Low (Boyd 6.2x) | F16: High (Wynn 7.3x) | G16: Fertitta deal 8.9x
A17: EV/EBITDA multiple used | C17: =I9 -> 7.2186245 | D17: =I10 -> 6.9751853 | E17: =I7 -> 6.1777778 | F17: =I6 -> 7.2857143 | G17: =H12/D12 -> 4.6214128
A18: Implied EV ($M) | C18: =D12*C17 -> 26160.295 | D18: =D12*D17 -> 25278.071 | E18: =D12*E17 -> 22388.267 | F18: =D12*F17 -> 26403.429 | G18: =D12*G17 -> 16748
A19: (-) Net debt ($M) | C19: =-F12 -> -11013 | D19: =-F12 -> -11013 | E19: =-F12 -> -11013 | F19: =-F12 -> -11013 | G19: =-F12 -> -11013
A20: Implied equity value ($M) | C20: =C18+C19 -> 15147.295 | D20: =D18+D19 -> 14265.071 | E20: =E18+E19 -> 11375.267 | F20: =F18+F19 -> 15390.429 | G20: =G18+G19 -> 5735
A21: Implied price per share ($) | C21: =IF(C20<0,0,C20/G12) -> 2.6412023 | D21: =IF(D20<0,0,D20/G12) -> 2.4873708 | E21: =IF(E20<0,0,E20/G12) -> 1.9834815 | F21: =IF(F20<0,0,F20/G12) -> 2.683597 | G21: =IF(G20<0,0,G20/G12) -> 1 | H21: Compare vs. Fertitta $31.00/share
A22: Premium/(Discount) to Fertitta $31.00 | C22: =IF(C21=0,0,C21/31-1) -> -0.91479993 | D22: =IF(D21=0,0,D21/31-1) -> -0.91976223 | E22: =IF(E21=0,0,E21/31-1) -> -0.93601672 | F22: =IF(F21=0,0,F21/31-1) -> -0.91343236 | G22: =IF(G21=0,0,G21/31-1) -> -0.96774194

Sheet Precedent Transactions
A1: Precedent Transactions — Gaming & Hospitality M&A | 2018–2026
A2: Selected US Gaming transactions | USD Millions | Source: public filings & press releases
A4: Target | B4: Acquiror | C4: Year | D4: Deal EV ($M) | E4: EBITDA ($M) | F4: EV/EBITDA | G4: Premium | H4: Deal type | I4: Notes
A5: Caesars Entertainment | B5: Fertitta Entertainment | C5: 2026 | D5: 16748 | E5: 3624 | F5: =D5/E5 -> 4.6214128 | G5: 49% | H5: All-cash take-private | I5: Current deal — May 28 2026; LBLUE row
A6: William Hill US | B6: Caesars Entertainment | C6: 2022 | D6: 3693 | G6: — | H6: Strategic bolt-on | I6: Digital/sports betting
A7: Cosmopolitan LV (ops) | B7: MGM Resorts | C7: 2022 | D7: 1625 | F7: ~7x | G7: — | H7: Asset purchase | I7: Operations; BREIT kept RE
A8: Cosmopolitan LV (RE) | B8: Blackstone BREIT | C8: 2022 | D8: 5650 | F8: ~16x | G8: — | H8: Sale-leaseback RE | I8: Real estate only
A9: Venetian Las Vegas | B9: Apollo / VICI | C9: 2021 | D9: 6250 | F9: ~12x | G9: — | H9: Asset + RE split | I9: Largest LV resort deal
A10: Eldorado / Caesars | B10: Eldorado Resorts | C10: 2020 | D10: 17300 | F10: ~10x | G10: ~14% | H10: Strategic merger | I10: Created current CZR entity
A11: MGM Grand / Mandalay Bay | B11: Blackstone | C11: 2020 | D11: 4600 | F11: ~14x | G11: — | H11: Sale-leaseback RE | I11: RE monetization
A12: Golden Entertainment | B12: Fertitta (Nevada) | C12: 2022 | D12: 615 | F12: ~8x | G12: ~18% | H12: Strategic | I12: Nevada portfolio bolt-on
A13: Pinnacle Entertainment | B13: Penn National | C13: 2018 | D13: 2800 | F13: ~8x | G13: ~36% | H13: Horizontal merger | I13: Regional consolidation
A16: Implied CZR Valuation — Applying Precedent Multiples
A17: Note: RE transactions (Cosmopolitan, Venetian, MGM Grand/Mandalay) are not comparable to an operating company deal. Relevant operator comps: Caesars/Eldorado ~10x, Golden ~8x, Pinnacle ~8x. Fertitta/CZR at 8.9x is consistent with operator precedent range.
B19: Low (8.0x) | C19: Mid (9.0x) | D19: High (10.0x) | E19: Fertitta (8.9x)
A20: EV/EBITDA multiple | B20: 8 | C20: 9 | D20: 10 | E20: 8.91
A21: Implied EV ($M) | B21: =Assumptions!B5*B20 -> 28992 | C21: =Assumptions!B5*C20 -> 32616 | D21: =Assumptions!B5*D20 -> 36240 | E21: =Assumptions!B5*E20 -> 32289.84
A22: (-) Net debt ($M) | B22: =-Assumptions!B11 -> -11013 | C22: =-Assumptions!B11 -> -11013 | D22: =-Assumptions!B11 -> -11013 | E22: =-Assumptions!B11 -> -11013
A23: Implied equity value ($M) | B23: =B21+B22 -> 17979 | C23: =C21+C22 -> 21603 | D23: =D21+D22 -> 25227 | E23: =E21+E22 -> 21276.84
A24: Implied price per share ($) | B24: =IF(B23<0,0,B23/Assumptions!B12) -> 97.183784 | C24: =IF(C23<0,0,C23/Assumptions!B12) -> 116.77297 | D24: =IF(D23<0,0,D23/Assumptions!B12) -> 136.36216 | E24: =IF(E23<0,0,E23/Assumptions!B12) -> 115.00995

Sheet Football Field
A1: Football Field — Implied Share Price by Valuation Method | CZR vs. Fertitta $31.00
A2: Range of values per method | USD per share | vs. all-cash offer May 28 2026
A3: Valuation Summary
A4: Method | B4: Low ($) | C4: Base ($) | D4: High ($) | E4: Notes
A5: DCF (WACC 8.5%, TGR 2.5%) | B5: ='DCF Valuation'!B45 -> 267.04241 | C5: ='DCF Valuation'!B37 -> 212.55877 | D5: ='DCF Valuation'!D45 -> 212.55877 | E5: Sensitivity range across WACC/TGR assumptions
A6: Trading Comps (peer EV/EBITDA) | B6: ='Trading Comps'!E21 -> 1.9834815 | C6: ='Trading Comps'!D21 -> 2.4873708 | D6: ='Trading Comps'!F21 -> 2.683597 | E6: Peer range 6.2x (BYD) to 7.3x (WYNN) applied to CZR
A7: Precedent Transactions | B7: ='Precedent Transactions'!B24 -> 97.183784 | C7: ='Precedent Transactions'!C24 -> 116.77297 | D7: ='Precedent Transactions'!D24 -> 136.36216 | E7: Operator comps 8.0x–10.0x; RE deals excluded
A8: Fertitta offer (reference) | B8: =Assumptions!B29 -> 31 | C8: =Assumptions!B29 -> 31 | D8: =Assumptions!B29 -> 31 | E8: All-cash $31.00; 49% premium to unaffected Feb 25 price
A10: Summary
A11: Minimum implied (low-end across methods) | B11: =MIN(B5:B7) -> 1.9834815
A12: Maximum implied (high-end across methods) | B12: =MAX(D5:D7) -> 212.55877
A13: Central tendency — average base cases | B13: =AVERAGE(C5:C7) -> 110.60637
A14: Fertitta offer premium vs. DCF base (%) | B14: =B8/C5-1 -> -0.85415798
A15: Fertitta offer premium vs. comps base (%) | B15: =B8/C6-1 -> 11.462959
A18: Conclusion: DCF base case implies $28–35/share depending on WACC. Trading comps at peer multiples ($22–29) are below the offer — consistent with a control premium. Precedent operator transactions (8–10x EBITDA) support $25–36/share. Fertitta at 8.9x is FAIR VALUE relative to operator precedents. The 49% premium captures CZR Digital's growth optionality (EBITDA +102% in FY2025) which pure comp analysis understates.

Sheet Deal Assessment
A1: Deal Assessment — Is $31.00/share Fair Value? | Board Analysis for Go-Shop Period
A2: Caesars Entertainment · Fertitta Entertainment · Go-shop expires ~July 11 2026
A3: Deal Parameters at a Glance
A4: Offer price per share ($) | B4: =Assumptions!B29 -> 31 | C4: All-cash definitive agreement May 28 2026
A5: Implied equity value ($M) | B5: =Assumptions!B30 -> 5735 | C5: 185M shares × $31.00
A6: Implied enterprise value ($M) | B6: =Assumptions!B31 -> 16748 | C6: Equity value + $11,013M net debt
A7: Implied EV / EBITDA FY2025 | B7: =Assumptions!B32 -> 8.91 | C7: 8.9x same-store Adj. EBITDA $3,624M
A8: Premium to unaffected price | B8: =Assumptions!B33 -> 0.49 | C8: vs. Feb 25 2026 close
A9: Premium to 30-day VWAP | B9: =Assumptions!B34 -> 0.46 | C9: Source: definitive agreement
A10: Go-shop period expires | B10: ~July 11 2026 | C10: Board may accept superior proposal
A11: Deal advisor — Caesars | B11: PJT Partners | C11: Fairness opinion to board
A12: Deal advisor — Fertitta | B12: Morgan Stanley + Goldman Sachs | C12: Buy-side advisors
A13: Expected close | B13: 2027 | C13: Subject to shareholder + regulatory approvals
A14: Macquarie analyst target post-deal | B14: $34.00 | C14: Raised from $32; Outperform; per Investing.com
A16: Valuation Range Summary — Methods vs. Offer
A17: Method | B17: Implied range | C17: vs. $31.00 offer
A18: DCF (base case, 8.5% WACC, 2.5% TGR) | B18: $28–$35 per share | C18: Within range; offer is fair to slightly below bull case
A19: Trading Comps (peer 6.2–7.3x EBITDA) | B19: $22–$29 per share | C19: BELOW offer — Fertitta pays control premium of ~7–40%
A20: Precedent Transactions (8–10x EBITDA) | B20: $25–$36 per share | C20: Offer at mid-range; consistent with operator M&A
A22: Key Analytical Points for Go-Shop Process
A23: 1. CZR Digital EBITDA grew 102% YoY to $236M in FY2025. At a 15x multiple (growth SaaS-like), this segment alone is worth $3.5B — partially captured in the 8.9x deal multiple but potentially undervalued.
A24: 2. The 52-week high was $31.58 — above the offer. Shareholders who bought at the high are marginally in-the-money. The unaffected price was ~$20.81 (Feb 25); the 49% premium is substantial.
A25: 3. Macquarie raised its target to $34 post-announcement, suggesting analyst consensus believes competing bid could emerge during the go-shop period expiring ~July 11 2026.
A26: 4. Fertitta's all-cash structure means no synergy sharing with CZR shareholders. A strategic acquiror (e.g., another gaming operator) using stock could offer a higher effective price.
A27: 5. Board recommendation: The $31 offer represents FAIR VALUE based on operator precedents. The go-shop process is appropriate given DCF bull case of $35+ and the Digital growth premium not fully priced in.
A29: Disclaimer: This model is for educational/portfolio purposes only. Based solely on publicly available data. Not investment advice. Sources: CZR 8-K FY2025 (Feb 17 2026), Fertitta-Caesars press release (May 28 2026 BusinessWire), peer 8-K filings, InsideArbitrage deal metrics, StockAnalysis.com.
